<?xml version="1.0" encoding="UTF-8"?>
<testng-results ignored="0" total="1" passed="0" failed="1" skipped="0">
  <reporter-output>
  </reporter-output>
  <suite started-at="2021-09-06T06:22:06 IST" name="Default suite" finished-at="2021-09-06T06:22:35 IST" duration-ms="29262">
    <groups>
    </groups>
    <test started-at="2021-09-06T06:22:06 IST" name="Default test" finished-at="2021-09-06T06:22:35 IST" duration-ms="29262">
      <class name="com.Framework.TestVagrant.Test_Case">
        <test-method is-config="true" signature="setUp()[pri:0, instance:com.Framework.TestVagrant.Test_Case@7205765b]" started-at="2021-09-06T06:22:06 IST" name="setUp" finished-at="2021-09-06T06:22:22 IST" duration-ms="16238" status="PASS">
          <reporter-output>
          </reporter-output>
        </test-method> <!-- setUp -->
        <test-method signature="TC01()[pri:0, instance:com.Framework.TestVagrant.Test_Case@7205765b]" started-at="2021-09-06T06:22:22 IST" name="TC01" finished-at="2021-09-06T06:22:33 IST" duration-ms="10849" status="FAIL">
          <exception class="com.Framework.TestVagrant.Customized_Exception">
            <message>
              <![CDATA[My Custom Exception gets called]]>
            </message>
            <full-stacktrace>
              <![CDATA[com.Framework.TestVagrant.Customized_Exception: My Custom Exception gets called
at com.Framework.TestVagrant.Test_Case.TC01(Test_Case.java:57)
at java.base/jdk.internal.reflect.NativeMethodAccessorImpl.invoke0(Native Method)
at java.base/jdk.internal.reflect.NativeMethodAccessorImpl.invoke(NativeMethodAccessorImpl.java:78)
at java.base/jdk.internal.reflect.DelegatingMethodAccessorImpl.invoke(DelegatingMethodAccessorImpl.java:43)
at java.base/java.lang.reflect.Method.invoke(Method.java:567)
at org.testng.internal.MethodInvocationHelper.invokeMethod(MethodInvocationHelper.java:133)
at org.testng.internal.TestInvoker.invokeMethod(TestInvoker.java:598)
at org.testng.internal.TestInvoker.invokeTestMethod(TestInvoker.java:173)
at org.testng.internal.MethodRunner.runInSequence(MethodRunner.java:46)
at org.testng.internal.TestInvoker$MethodInvocationAgent.invoke(TestInvoker.java:824)
at org.testng.internal.TestInvoker.invokeTestMethods(TestInvoker.java:146)
at org.testng.internal.TestMethodWorker.invokeTestMethods(TestMethodWorker.java:146)
at org.testng.internal.TestMethodWorker.run(TestMethodWorker.java:128)
at java.base/java.util.ArrayList.forEach(ArrayList.java:1511)
at org.testng.TestRunner.privateRun(TestRunner.java:794)
at org.testng.TestRunner.run(TestRunner.java:596)
at org.testng.SuiteRunner.runTest(SuiteRunner.java:377)
at org.testng.SuiteRunner.runSequentially(SuiteRunner.java:371)
at org.testng.SuiteRunner.privateRun(SuiteRunner.java:332)
at org.testng.SuiteRunner.run(SuiteRunner.java:276)
at org.testng.SuiteRunnerWorker.runSuite(SuiteRunnerWorker.java:53)
at org.testng.SuiteRunnerWorker.run(SuiteRunnerWorker.java:96)
at org.testng.TestNG.runSuitesSequentially(TestNG.java:1212)
at org.testng.TestNG.runSuitesLocally(TestNG.java:1134)
at org.testng.TestNG.runSuites(TestNG.java:1063)
at org.testng.TestNG.run(TestNG.java:1031)
at org.testng.remote.AbstractRemoteTestNG.run(AbstractRemoteTestNG.java:115)
at org.testng.remote.RemoteTestNG.initAndRun(RemoteTestNG.java:251)
at org.testng.remote.RemoteTestNG.main(RemoteTestNG.java:77)
]]>
            </full-stacktrace>
          </exception> <!-- com.Framework.TestVagrant.Customized_Exception -->
          <reporter-output>
          </reporter-output>
        </test-method> <!-- TC01 -->
        <test-method is-config="true" signature="closeBrowsers()[pri:0, instance:com.Framework.TestVagrant.Test_Case@7205765b]" started-at="2021-09-06T06:22:33 IST" name="closeBrowsers" finished-at="2021-09-06T06:22:35 IST" duration-ms="2063" status="PASS">
          <reporter-output>
          </reporter-output>
        </test-method> <!-- closeBrowsers -->
      </class> <!-- com.Framework.TestVagrant.Test_Case -->
    </test> <!-- Default test -->
  </suite> <!-- Default suite -->
</testng-results>
